// We can repair our program in a very simple way â€“ all we have to do here is add an ellipsis branch, which will be responsible for taking care of all the orphaned exceptions.

#include <iostream>
#include "../myFunctions.h"
using namespace std;

void function(int i)
{
    switch(i) {
        case 0: throw domain_error("0");
        case 1: throw logic_error("1");
        case 2: throw exception();
        case 3: throw range_error("2");
        case 4: throw "so bad";
    }
}

int main()
{
    for(int i = 0; i < 5; i++) {
        try {
            function(i);
        }
        catch(exception &ex) {
            cout << "Exception: " << ex.what() << endl;
        }
        catch(...) {
            cout << "Something bad happened" << endl;
        }
    }

    askOS();
    return 0;
}

/*
Output:

Exception: 0
Exception: 1
Exception: std::exception
Exception: 2
Something bad happened
*/